Unhandled exception in thread started by <function check_errors.<locals>.wrapper at 0x7f9d54d6cea0>
Traceback (most recent call last):
  File "/usr/local/lib/python3.5/site-packages/django/db/backends/base/base.py", line 213, in ensure_connection
    self.connect()
  File "/usr/local/lib/python3.5/site-packages/django/db/backends/base/base.py", line 189, in connect
    self.connection = self.get_new_connection(conn_params)
  File "/usr/local/lib/python3.5/site-packages/django/db/backends/mysql/base.py", line 274, in get_new_connection
    conn = Database.connect(**conn_params)
  File "/usr/local/lib/python3.5/site-packages/pymysql/__init__.py", line 90, in Connect
    return Connection(*args, **kwargs)
  File "/usr/local/lib/python3.5/site-packages/pymysql/connections.py", line 706, in __init__
    self.connect()
  File "/usr/local/lib/python3.5/site-packages/pymysql/connections.py", line 931, in connect
    self._get_server_information()
  File "/usr/local/lib/python3.5/site-packages/pymysql/connections.py", line 1245, in _get_server_information
    packet = self._read_packet()
  File "/usr/local/lib/python3.5/site-packages/pymysql/connections.py", line 1014, in _read_packet
    packet.check_error()
  File "/usr/local/lib/python3.5/site-packages/pymysql/connections.py", line 393, in check_error
    err.raise_mysql_exception(self._data)
  File "/usr/local/lib/python3.5/site-packages/pymysql/err.py", line 107, in raise_mysql_exception
    raise errorclass(errno, errval)
pymysql.err.InternalError: (1130, "Host '47.94.93.174' is not allowed to connect to this MySQL server")

The above exception was the direct cause of the following exception:

Traceback (most recent call last):
  File "/usr/local/lib/python3.5/site-packages/django/utils/autoreload.py", line 228, in wrapper
    fn(*args, **kwargs)
  File "/usr/local/lib/python3.5/site-packages/django/core/management/commands/runserver.py", line 125, in inner_run
    self.check(display_num_errors=True)
  File "/usr/local/lib/python3.5/site-packages/django/core/management/base.py", line 359, in check
    include_deployment_checks=include_deployment_checks,
  File "/usr/local/lib/python3.5/site-packages/django/core/management/base.py", line 346, in _run_checks
    return checks.run_checks(**kwargs)
  File "/usr/local/lib/python3.5/site-packages/django/core/checks/registry.py", line 81, in run_checks
    new_errors = check(app_configs=app_configs)
  File "/usr/local/lib/python3.5/site-packages/django/core/checks/model_checks.py", line 30, in check_all_models
    errors.extend(model.check(**kwargs))
  File "/usr/local/lib/python3.5/site-packages/django/db/models/base.py", line 1283, in check
    errors.extend(cls._check_fields(**kwargs))
  File "/usr/local/lib/python3.5/site-packages/django/db/models/base.py", line 1358, in _check_fields
    errors.extend(field.check(**kwargs))
  File "/usr/local/lib/python3.5/site-packages/django/db/models/fields/__init__.py", line 913, in check
    errors = super(AutoField, self).check(**kwargs)
  File "/usr/local/lib/python3.5/site-packages/django/db/models/fields/__init__.py", line 219, in check
    errors.extend(self._check_backend_specific_checks(**kwargs))
  File "/usr/local/lib/python3.5/site-packages/django/db/models/fields/__init__.py", line 322, in _check_backend_specific_checks
    return connections[db].validation.check_field(self, **kwargs)
  File "/usr/local/lib/python3.5/site-packages/django/db/backends/mysql/validation.py", line 49, in check_field
    field_type = field.db_type(self.connection)
  File "/usr/local/lib/python3.5/site-packages/django/db/models/fields/__init__.py", line 644, in db_type
    return connection.data_types[self.get_internal_type()] % data
  File "/usr/local/lib/python3.5/site-packages/django/utils/functional.py", line 35, in __get__
    res = instance.__dict__[self.name] = self.func(instance)
  File "/usr/local/lib/python3.5/site-packages/django/db/backends/mysql/base.py", line 174, in data_types
    if self.features.supports_microsecond_precision:
  File "/usr/local/lib/python3.5/site-packages/django/utils/functional.py", line 35, in __get__
    res = instance.__dict__[self.name] = self.func(instance)
  File "/usr/local/lib/python3.5/site-packages/django/db/backends/mysql/features.py", line 53, in supports_microsecond_precision
    return self.connection.mysql_version >= (5, 6, 4) and Database.version_info >= (1, 2, 5)
  File "/usr/local/lib/python3.5/site-packages/django/utils/functional.py", line 35, in __get__
    res = instance.__dict__[self.name] = self.func(instance)
  File "/usr/local/lib/python3.5/site-packages/django/db/backends/mysql/base.py", line 385, in mysql_version
    with self.temporary_connection() as cursor:
  File "/usr/local/lib/python3.5/contextlib.py", line 59, in __enter__
    return next(self.gen)
  File "/usr/local/lib/python3.5/site-packages/django/db/backends/base/base.py", line 591, in temporary_connection
    cursor = self.cursor()
  File "/usr/local/lib/python3.5/site-packages/django/db/backends/base/base.py", line 254, in cursor
    return self._cursor()
  File "/usr/local/lib/python3.5/site-packages/django/db/backends/base/base.py", line 229, in _cursor
    self.ensure_connection()
  File "/usr/local/lib/python3.5/site-packages/django/db/backends/base/base.py", line 213, in ensure_connection
    self.connect()
  File "/usr/local/lib/python3.5/site-packages/django/db/utils.py", line 94, in __exit__
    six.reraise(dj_exc_type, dj_exc_value, traceback)
  File "/usr/local/lib/python3.5/site-packages/django/utils/six.py", line 685, in reraise
    raise value.with_traceback(tb)
  File "/usr/local/lib/python3.5/site-packages/django/db/backends/base/base.py", line 213, in ensure_connection
    self.connect()
  File "/usr/local/lib/python3.5/site-packages/django/db/backends/base/base.py", line 189, in connect
    self.connection = self.get_new_connection(conn_params)
  File "/usr/local/lib/python3.5/site-packages/django/db/backends/mysql/base.py", line 274, in get_new_connection
    conn = Database.connect(**conn_params)
  File "/usr/local/lib/python3.5/site-packages/pymysql/__init__.py", line 90, in Connect
    return Connection(*args, **kwargs)
  File "/usr/local/lib/python3.5/site-packages/pymysql/connections.py", line 706, in __init__
    self.connect()
  File "/usr/local/lib/python3.5/site-packages/pymysql/connections.py", line 931, in connect
    self._get_server_information()
  File "/usr/local/lib/python3.5/site-packages/pymysql/connections.py", line 1245, in _get_server_information
    packet = self._read_packet()
  File "/usr/local/lib/python3.5/site-packages/pymysql/connections.py", line 1014, in _read_packet
    packet.check_error()
  File "/usr/local/lib/python3.5/site-packages/pymysql/connections.py", line 393, in check_error
    err.raise_mysql_exception(self._data)
  File "/usr/local/lib/python3.5/site-packages/pymysql/err.py", line 107, in raise_mysql_exception
    raise errorclass(errno, errval)
django.db.utils.InternalError: (1130, "Host '47.94.93.174' is not allowed to connect to this MySQL server")
Performing system checks...

